[2025-03-09T05:54:45.881+0000] {taskinstance.py:1159} INFO - Dependencies all met for dep_context=non-requeueable deps ti=<TaskInstance: dbt_bigquery.run_dbt manual__2025-03-09T05:49:41.658769+00:00 [queued]>
[2025-03-09T05:54:45.893+0000] {taskinstance.py:1159} INFO - Dependencies all met for dep_context=requeueable deps ti=<TaskInstance: dbt_bigquery.run_dbt manual__2025-03-09T05:49:41.658769+00:00 [queued]>
[2025-03-09T05:54:45.894+0000] {taskinstance.py:1361} INFO - Starting attempt 2 of 2
[2025-03-09T05:54:45.909+0000] {taskinstance.py:1382} INFO - Executing <Task(BashOperator): run_dbt> on 2025-03-09 05:49:41.658769+00:00
[2025-03-09T05:54:45.913+0000] {standard_task_runner.py:57} INFO - Started process 578 to run task
[2025-03-09T05:54:45.917+0000] {standard_task_runner.py:84} INFO - Running: ['***', 'tasks', 'run', 'dbt_bigquery', 'run_dbt', 'manual__2025-03-09T05:49:41.658769+00:00', '--job-id', '5', '--raw', '--subdir', 'DAGS_FOLDER/dbt_bigquery.py', '--cfg-path', '/tmp/tmppz8cwrdo']
[2025-03-09T05:54:45.920+0000] {standard_task_runner.py:85} INFO - Job 5: Subtask run_dbt
[2025-03-09T05:54:45.940+0000] {logging_mixin.py:151} WARNING - /home/***/.local/lib/python3.8/site-packages/***/settings.py:195 DeprecationWarning: The sql_alchemy_conn option in [core] has been moved to the sql_alchemy_conn option in [database] - the old setting has been used, but please update your config.
[2025-03-09T05:54:45.980+0000] {task_command.py:415} INFO - Running <TaskInstance: dbt_bigquery.run_dbt manual__2025-03-09T05:49:41.658769+00:00 [running]> on host 9ac17e6c53e7
[2025-03-09T05:54:46.068+0000] {taskinstance.py:1660} INFO - Exporting env vars: AIRFLOW_CTX_DAG_OWNER='***' AIRFLOW_CTX_DAG_ID='dbt_bigquery' AIRFLOW_CTX_TASK_ID='run_dbt' AIRFLOW_CTX_EXECUTION_DATE='2025-03-09T05:49:41.658769+00:00' AIRFLOW_CTX_TRY_NUMBER='2' AIRFLOW_CTX_DAG_RUN_ID='manual__2025-03-09T05:49:41.658769+00:00'
[2025-03-09T05:54:46.070+0000] {subprocess.py:63} INFO - Tmp dir root location: /tmp
[2025-03-09T05:54:46.072+0000] {subprocess.py:75} INFO - Running command: ['/bin/bash', '-c', 'dbt run --profiles-dir /opt/***/de_project']
[2025-03-09T05:54:46.083+0000] {subprocess.py:86} INFO - Output:
[2025-03-09T05:54:46.085+0000] {subprocess.py:93} INFO - /bin/bash: line 1: dbt: command not found
[2025-03-09T05:54:46.086+0000] {subprocess.py:97} INFO - Command exited with return code 127
[2025-03-09T05:54:46.104+0000] {taskinstance.py:1943} ERROR - Task failed with exception
Traceback (most recent call last):
  File "/home/airflow/.local/lib/python3.8/site-packages/airflow/operators/bash.py", line 210, in execute
    raise AirflowException(
airflow.exceptions.AirflowException: Bash command failed. The command returned a non-zero exit code 127.
[2025-03-09T05:54:46.109+0000] {taskinstance.py:1400} INFO - Marking task as FAILED. dag_id=dbt_bigquery, task_id=run_dbt, execution_date=20250309T054941, start_date=20250309T055445, end_date=20250309T055446
[2025-03-09T05:54:46.125+0000] {standard_task_runner.py:104} ERROR - Failed to execute job 5 for task run_dbt (Bash command failed. The command returned a non-zero exit code 127.; 578)
[2025-03-09T05:54:46.139+0000] {local_task_job_runner.py:228} INFO - Task exited with return code 1
[2025-03-09T05:54:46.159+0000] {taskinstance.py:2784} INFO - 0 downstream tasks scheduled from follow-on schedule check
