[2025-03-09T05:54:44.816+0000] {logging_mixin.py:151} WARNING - /home/***/.local/lib/python3.8/site-packages/***/utils/sqlalchemy.py:124 DeprecationWarning: The sql_alchemy_conn option in [core] has been moved to the sql_alchemy_conn option in [database] - the old setting has been used, but please update your config.
[2025-03-09T05:54:44.828+0000] {taskinstance.py:1159} INFO - Dependencies all met for dep_context=non-requeueable deps ti=<TaskInstance: dbt_bigquery.run_dbt scheduled__2025-03-08T00:00:00+00:00 [queued]>
[2025-03-09T05:54:44.839+0000] {taskinstance.py:1159} INFO - Dependencies all met for dep_context=requeueable deps ti=<TaskInstance: dbt_bigquery.run_dbt scheduled__2025-03-08T00:00:00+00:00 [queued]>
[2025-03-09T05:54:44.840+0000] {taskinstance.py:1361} INFO - Starting attempt 2 of 2
[2025-03-09T05:54:44.854+0000] {taskinstance.py:1382} INFO - Executing <Task(BashOperator): run_dbt> on 2025-03-08 00:00:00+00:00
[2025-03-09T05:54:44.858+0000] {standard_task_runner.py:57} INFO - Started process 575 to run task
[2025-03-09T05:54:44.862+0000] {standard_task_runner.py:84} INFO - Running: ['***', 'tasks', 'run', 'dbt_bigquery', 'run_dbt', 'scheduled__2025-03-08T00:00:00+00:00', '--job-id', '4', '--raw', '--subdir', 'DAGS_FOLDER/dbt_bigquery.py', '--cfg-path', '/tmp/tmphykeu04g']
[2025-03-09T05:54:44.865+0000] {standard_task_runner.py:85} INFO - Job 4: Subtask run_dbt
[2025-03-09T05:54:44.892+0000] {logging_mixin.py:151} WARNING - /home/***/.local/lib/python3.8/site-packages/***/settings.py:195 DeprecationWarning: The sql_alchemy_conn option in [core] has been moved to the sql_alchemy_conn option in [database] - the old setting has been used, but please update your config.
[2025-03-09T05:54:44.951+0000] {task_command.py:415} INFO - Running <TaskInstance: dbt_bigquery.run_dbt scheduled__2025-03-08T00:00:00+00:00 [running]> on host 9ac17e6c53e7
[2025-03-09T05:54:44.972+0000] {logging_mixin.py:151} WARNING - /home/***/.local/lib/python3.8/site-packages/***/utils/sqlalchemy.py:124 DeprecationWarning: The sql_alchemy_conn option in [core] has been moved to the sql_alchemy_conn option in [database] - the old setting has been used, but please update your config.
[2025-03-09T05:54:45.065+0000] {taskinstance.py:1660} INFO - Exporting env vars: AIRFLOW_CTX_DAG_OWNER='***' AIRFLOW_CTX_DAG_ID='dbt_bigquery' AIRFLOW_CTX_TASK_ID='run_dbt' AIRFLOW_CTX_EXECUTION_DATE='2025-03-08T00:00:00+00:00' AIRFLOW_CTX_TRY_NUMBER='2' AIRFLOW_CTX_DAG_RUN_ID='scheduled__2025-03-08T00:00:00+00:00'
[2025-03-09T05:54:45.068+0000] {subprocess.py:63} INFO - Tmp dir root location: /tmp
[2025-03-09T05:54:45.069+0000] {subprocess.py:75} INFO - Running command: ['/bin/bash', '-c', 'dbt run --profiles-dir /opt/***/de_project']
[2025-03-09T05:54:45.081+0000] {subprocess.py:86} INFO - Output:
[2025-03-09T05:54:45.082+0000] {subprocess.py:93} INFO - /bin/bash: line 1: dbt: command not found
[2025-03-09T05:54:45.083+0000] {subprocess.py:97} INFO - Command exited with return code 127
[2025-03-09T05:54:45.096+0000] {taskinstance.py:1943} ERROR - Task failed with exception
Traceback (most recent call last):
  File "/home/airflow/.local/lib/python3.8/site-packages/airflow/operators/bash.py", line 210, in execute
    raise AirflowException(
airflow.exceptions.AirflowException: Bash command failed. The command returned a non-zero exit code 127.
[2025-03-09T05:54:45.101+0000] {taskinstance.py:1400} INFO - Marking task as FAILED. dag_id=dbt_bigquery, task_id=run_dbt, execution_date=20250308T000000, start_date=20250309T055444, end_date=20250309T055445
[2025-03-09T05:54:45.117+0000] {standard_task_runner.py:104} ERROR - Failed to execute job 4 for task run_dbt (Bash command failed. The command returned a non-zero exit code 127.; 575)
[2025-03-09T05:54:45.126+0000] {local_task_job_runner.py:228} INFO - Task exited with return code 1
[2025-03-09T05:54:45.147+0000] {taskinstance.py:2784} INFO - 0 downstream tasks scheduled from follow-on schedule check
