[2025-03-09T05:49:42.391+0000] {logging_mixin.py:151} WARNING - /home/***/.local/lib/python3.8/site-packages/***/utils/sqlalchemy.py:124 DeprecationWarning: The sql_alchemy_conn option in [core] has been moved to the sql_alchemy_conn option in [database] - the old setting has been used, but please update your config.
[2025-03-09T05:49:42.403+0000] {taskinstance.py:1159} INFO - Dependencies all met for dep_context=non-requeueable deps ti=<TaskInstance: dbt_bigquery.run_dbt scheduled__2025-03-08T00:00:00+00:00 [queued]>
[2025-03-09T05:49:42.420+0000] {taskinstance.py:1159} INFO - Dependencies all met for dep_context=requeueable deps ti=<TaskInstance: dbt_bigquery.run_dbt scheduled__2025-03-08T00:00:00+00:00 [queued]>
[2025-03-09T05:49:42.421+0000] {taskinstance.py:1361} INFO - Starting attempt 1 of 2
[2025-03-09T05:49:42.436+0000] {taskinstance.py:1382} INFO - Executing <Task(BashOperator): run_dbt> on 2025-03-08 00:00:00+00:00
[2025-03-09T05:49:42.441+0000] {standard_task_runner.py:57} INFO - Started process 519 to run task
[2025-03-09T05:49:42.445+0000] {standard_task_runner.py:84} INFO - Running: ['***', 'tasks', 'run', 'dbt_bigquery', 'run_dbt', 'scheduled__2025-03-08T00:00:00+00:00', '--job-id', '2', '--raw', '--subdir', 'DAGS_FOLDER/dbt_bigquery.py', '--cfg-path', '/tmp/tmpq5g8ol5x']
[2025-03-09T05:49:42.450+0000] {standard_task_runner.py:85} INFO - Job 2: Subtask run_dbt
[2025-03-09T05:49:42.520+0000] {logging_mixin.py:151} WARNING - /home/***/.local/lib/python3.8/site-packages/***/settings.py:195 DeprecationWarning: The sql_alchemy_conn option in [core] has been moved to the sql_alchemy_conn option in [database] - the old setting has been used, but please update your config.
[2025-03-09T05:49:42.666+0000] {task_command.py:415} INFO - Running <TaskInstance: dbt_bigquery.run_dbt scheduled__2025-03-08T00:00:00+00:00 [running]> on host 9ac17e6c53e7
[2025-03-09T05:49:42.717+0000] {logging_mixin.py:151} WARNING - /home/***/.local/lib/python3.8/site-packages/***/utils/sqlalchemy.py:124 DeprecationWarning: The sql_alchemy_conn option in [core] has been moved to the sql_alchemy_conn option in [database] - the old setting has been used, but please update your config.
[2025-03-09T05:49:42.958+0000] {taskinstance.py:1660} INFO - Exporting env vars: AIRFLOW_CTX_DAG_OWNER='***' AIRFLOW_CTX_DAG_ID='dbt_bigquery' AIRFLOW_CTX_TASK_ID='run_dbt' AIRFLOW_CTX_EXECUTION_DATE='2025-03-08T00:00:00+00:00' AIRFLOW_CTX_TRY_NUMBER='1' AIRFLOW_CTX_DAG_RUN_ID='scheduled__2025-03-08T00:00:00+00:00'
[2025-03-09T05:49:42.972+0000] {subprocess.py:63} INFO - Tmp dir root location: /tmp
[2025-03-09T05:49:42.982+0000] {subprocess.py:75} INFO - Running command: ['/bin/bash', '-c', 'dbt run --profiles-dir /opt/***/de_project']
[2025-03-09T05:49:43.044+0000] {subprocess.py:86} INFO - Output:
[2025-03-09T05:49:43.090+0000] {subprocess.py:93} INFO - /bin/bash: line 1: dbt: command not found
[2025-03-09T05:49:43.092+0000] {subprocess.py:97} INFO - Command exited with return code 127
[2025-03-09T05:49:43.123+0000] {taskinstance.py:1943} ERROR - Task failed with exception
Traceback (most recent call last):
  File "/home/airflow/.local/lib/python3.8/site-packages/airflow/operators/bash.py", line 210, in execute
    raise AirflowException(
airflow.exceptions.AirflowException: Bash command failed. The command returned a non-zero exit code 127.
[2025-03-09T05:49:43.132+0000] {taskinstance.py:1400} INFO - Marking task as UP_FOR_RETRY. dag_id=dbt_bigquery, task_id=run_dbt, execution_date=20250308T000000, start_date=20250309T054942, end_date=20250309T054943
[2025-03-09T05:49:43.165+0000] {standard_task_runner.py:104} ERROR - Failed to execute job 2 for task run_dbt (Bash command failed. The command returned a non-zero exit code 127.; 519)
[2025-03-09T05:49:43.189+0000] {local_task_job_runner.py:228} INFO - Task exited with return code 1
[2025-03-09T05:49:43.246+0000] {taskinstance.py:2784} INFO - 0 downstream tasks scheduled from follow-on schedule check
